Workbook

Sheet florauruguaya_V_4
A1: wfo_ID | B1: Hábito | C1: Familia | D1: Column1 | E1: Nombre | F1: Autor | G1: Pub. | H1: Hábito | I1: Formaciones vegetales | J1: Forma de vida | K1: Link stand alone
A2: =VLOOKUP(especies_20260604_152756[[#This Row],[Column1]],output__33[[input_name_string]:[wfo_id2]],2,FALSE) -> wfo-0000646051 | B2: Sufrútice | C2: Acanthaceae | D2: Dicliptera squarrosa Nees | E2: Dicliptera squarrosa | F2: Nees | G2: Fl. Bras. [Martius] 9: 161, 1847. | H2: Sufrútice | I2: Bosques ribereños, Algarrobales, Matorrales mesófilos, Matorrales psamófilos, Pastizales xerófilos | J2: Caméfita | K2: https://florauruguaya.org/taxonomias/dicliptera-squarrosa
A3: =VLOOKUP(especies_20260604_152756[[#This Row],[Column1]],output__33[[input_name_string]:[wfo_id2]],2,FALSE) -> wfo-1200030165 | B3: Hierba perenne | C3: Acanthaceae | D3: Dyschoriste humilis (Nees) Lindau | E3: Dyschoriste humilis | F3: (Nees) Lindau | G3: Bot. Jahrb. Syst. 19(4): 15, 1894. | H3: Hierba perenne | I3: Algarrobales, Matorrales xerófilos, Pastizales xerófilos | J3: Caméfita | K3: https://florauruguaya.org/taxonomias/dyschoriste-humilis
A4: =VLOOKUP(especies_20260604_152756[[#This Row],[Column1]],output__33[[input_name_string]:[wfo_id2]],2,FALSE) -> wfo-0000658315 | B4: Hierba perenne | C4: Acanthaceae | D4: Dyschoriste hygrophiloides (Nees) Kuntze | E4: Dyschoriste hygrophiloides | F4: (Nees) Kuntze | G4: Revis. Gen. Pl. 2: 486, 1891. | H4: Hierba perenne | I4: Pastizales xerófilos, Pastizales mesófilos | K4: https://florauruguaya.org/taxonomias/dyschoriste-hygrophiloides
A5: =VLOOKUP(especies_20260604_152756[[#This Row],[Column1]],output__33[[input_name_string]:[wfo_id2]],2,FALSE) -> wfo-0000726781 | B5: Hierba perenne | C5: Acanthaceae | D5: Hygrophila costata Nees & T.Nees | E5: Hygrophila costata | F5: Nees & T.Nees | G5: Pl. Hort. Bonn. Icon. 7, t. 3, 1824. | H5: Hierba perenne | I5: Bosques ribereños, Bosques higrófilos, Algarrobales, Palmares, Herbazales hidrófilos | J5: Caméfita | K5: https://florauruguaya.org/taxonomias/hygrophila-costata
A6: =VLOOKUP(especies_20260604_152756[[#This Row],[Column1]],output__33[[input_name_string]:[wfo_id2]],2,FALSE) -> wfo-0000726797 | B6: Hierba perenne | C6: Acanthaceae | D6: Hygrophila guianensis Nees | E6: Hygrophila guianensis | F6: Nees | G6: London J. Bot. 4: 634, 1845. | H6: Hierba perenne | I6: Bosques ribereños | K6: https://florauruguaya.org/taxonomias/hygrophila-guianensis
A7: =VLOOKUP(especies_20260604_152756[[#This Row],[Column1]],output__33[[input_name_string]:[wfo_id2]],2,FALSE) -> wfo-0001043972 | B7: Hierba perenne | C7: Acanthaceae | D7: Justicia axillaris (Nees) Lindau | E7: Justicia axillaris | F7: (Nees) Lindau | G7: Nat. Pflanzenfam. [Engler & Prantl] 4(3b): 350, 1895. | H7: Hierba perenne | I7: Matorrales xerófilos, Pastizales xerófilos | K7: https://florauruguaya.org/taxonomias/justicia-axillaris
A8: =VLOOKUP(especies_20260604_152756[[#This Row],[Column1]],output__33[[input_name_string]:[wfo_id2]],2,FALSE) -> wfo-0000354192 | B8: Sufrútice | C8: Acanthaceae | D8: Justicia brasiliana Roth | E8: Justicia brasiliana | F8: Roth | G8: Nov. Pl. Sp. 17, 1821. | H8: Sufrútice | I8: Bosques de quebradas, Bosques ribereños | J8: Caméfita | K8: https://florauruguaya.org/taxonomias/justicia-brasiliana
A9: =VLOOKUP(especies_20260604_152756[[#This Row],[Column1]],output__33[[input_name_string]:[wfo_id2]],2,FALSE) -> wfo-0000354453 | B9: Hierba perenne | C9: Acanthaceae | D9: Justicia comata (L.) Lam. | E9: Justicia comata | F9: (L.) Lam. | G9: Encycl. [J. Lamarck & al.] 1(2): 632, 1785. | H9: Hierba perenne | I9: Bosques ribereños, Herbazales hidrófilos | J9: Caméfita | K9: https://florauruguaya.org/taxonomias/justicia-comata
A10: =VLOOKUP(especies_20260604_152756[[#This Row],[Column1]],output__33[[input_name_string]:[wfo_id2]],2,FALSE) -> wfo-0000355947 | B10: Hierba perenne | C10: Acanthaceae | D10: Justicia laevilinguis (Nees) Lindau | E10: Justicia laevilinguis | F10: (Nees) Lindau | G10: Bot. Jahrb. Syst. 19(4): 20, 1894. | H10: Hierba perenne | I10: Algarrobales, Pastizales higrófilos, Herbazales hidrófilos | J10: Caméfita | K10: https://florauruguaya.org/taxonomias/justicia-laevilinguis
A11: =VLOOKUP(especies_20260604_152756[[#This Row],[Column1]],output__33[[input_name_string]:[wfo_id2]],2,FALSE) -> wfo-0001044021 | B11: Hierba perenne | C11: Acanthaceae | D11: Justicia oblonga (Nees) Lindau | E11: Justicia oblonga | F11: (Nees) Lindau | G11: Nat. Pflanzenfam. [Engler & Prantl] 4(3b): 350, 1895. | H11: Hierba perenne | I11: Bosques ribereños | K11: https://florauruguaya.org/taxonomias/justicia-oblonga
A12: =VLOOKUP(especies_20260604_152756[[#This Row],[Column1]],output__33[[input_name_string]:[wfo_id2]],2,FALSE) -> wfo-0001044033 | B12: Hierba perenne | C12: Acanthaceae | D12: Justicia polygaloides (S.Moore) Lindau | E12: Justicia polygaloides | F12: (S.Moore) Lindau | G12: Bull. Herb. Boissier 2(3): 633, 1933. | H12: Hierba perenne | I12: Pastizales higrófilos | K12: https://florauruguaya.org/taxonomias/justicia-polygaloides
A13: =VLOOKUP(especies_20260604_152756[[#This Row],[Column1]],output__33[[input_name_string]:[wfo_id2]],2,FALSE) -> wfo-0001045288 | B13: Arbusto | C13: Acanthaceae | D13: Justicia tweedieana (Nees) Griseb. | E13: Justicia tweedieana | F13: (Nees) Griseb. | G13: Abh. Königl. Ges. Wiss. Göttingen 19: 225, 1874. | H13: Arbusto | I13: Algarrobales, Pastizales xerófilos, Herbazales halófilos | J13: Nanofanerófita | K13: https://florauruguaya.org/taxonomias/justicia-tweedieana
A14: =VLOOKUP(especies_20260604_152756[[#This Row],[Column1]],output__33[[input_name_string]:[wfo_id2]],2,FALSE) -> wfo-0000398720 | B14: Arbusto | C14: Acanthaceae | D14: Poikilacanthus glandulosus (Nees) Ariza | E14: Poikilacanthus glandulosus | F14: (Nees) Ariza | G14: Kurtziana 17: 159, 1984. | H14: Arbusto | I14: Bosques ribereños, Matorrales mesófilos | J14: Nanofanerófita | K14: https://florauruguaya.org/taxonomias/poikilacanthus-glandulosus
A15: =VLOOKUP(especies_20260604_152756[[#This Row],[Column1]],output__33[[input_name_string]:[wfo_id2]],2,FALSE) -> wfo-0000737403 | B15: Arbusto | C15: Acanthaceae | D15: Ruellia angustiflora (Nees) Lindau ex Rambo | E15: Ruellia angustiflora | F15: (Nees) Lindau ex Rambo | G15: Iheringia, Bot. 12: 23, 1964. | H15: Arbusto | I15: Bosques de quebradas | J15: Nanofanerófita | K15: https://florauruguaya.org/taxonomias/ruellia-angustiflora
A16: =VLOOKUP(especies_20260604_152756[[#This Row],[Column1]],output__33[[input_name_string]:[wfo_id2]],2,FALSE) -> wfo-0001045381 | B16: Hierba perenne | C16: Acanthaceae | D16: Ruellia hygrophila Mart. | E16: Ruellia hygrophila | F16: Mart. | G16: Flora 24(2): 65, 1841. | H16: Hierba perenne | I16: Matorrales xerófilos, Herbazales hidrófilos | J16: Hemicriptófita | K16: https://florauruguaya.org/taxonomias/ruellia-hygrophila
A17: =VLOOKUP(especies_20260604_152756[[#This Row],[Column1]],output__33[[input_name_string]:[wfo_id2]],2,FALSE) -> wfo-0000401879 | B17: Hierba perenne | C17: Acanthaceae | D17: Ruellia hypericoides (Nees) Lindau | E17: Ruellia hypericoides | F17: (Nees) Lindau | G17: Bot. Jahrb. Syst. 19(4): 16, 1894. | H17: Hierba perenne | I17: Pastizales xerófilos | J17: Hemicriptófita | K17: https://florauruguaya.org/taxonomias/ruellia-hypericoides
A18: =VLOOKUP(especies_20260604_152756[[#This Row],[Column1]],output__33[[input_name_string]:[wfo_id2]],2,FALSE) -> wfo-0001045173 | B18: Hierba perenne | C18: Acanthaceae | D18: Ruellia morongii Britton | E18: Ruellia morongii | F18: Britton | G18: Ann. New York Acad. Sci. 7: 192, 1893. | H18: Hierba perenne | I18: Pastizales xerófilos, Pastizales mesófilos | J18: Hemicriptófita | K18: https://florauruguaya.org/taxonomias/ruellia-morongii
A19: =VLOOKUP(especies_20260604_152756[[#This Row],[Column1]],output__33[[input_name_string]:[wfo_id2]],2,FALSE) -> wfo-0000400995 | B19: Hierba perenne | C19: Acanthaceae | D19: Ruellia simplex C.Wright | E19: Ruellia simplex | F19: C.Wright | G19: Anales Acad. Ci. Méd. Habana 6(41): 321, 1870. | H19: Hierba perenne | I19: Bosques ribereños, Algarrobales, Pastizales higrófilos, Herbazales halófilos | J19: Caméfita | K19: https://florauruguaya.org/taxonomias/ruellia-simplex
A20: =VLOOKUP(especies_20260604_152756[[#This Row],[Column1]],output__33[[input_name_string]:[wfo_id2]],2,FALSE) -> wfo-0001045348 | B20: Hierba perenne | C20: Acanthaceae | D20: Stenandrium diphyllum Nees | E20: Stenandrium diphyllum | F20: Nees | G20: Fl. Bras. [Martius] 9: 75, 1847. | H20: Hierba perenne | I20: Matorrales xerófilos, Pastizales xerófilos | J20: Hemicriptófita | K20: https://florauruguaya.org/taxonomias/stenandrium-diphyllum
A21: =VLOOKUP(especies_20260604_152756[[#This Row],[Column1]],output__33[[input_name_string]:[wfo_id2]],2,FALSE) -> wfo-0001044785 | B21: Hierba perenne | C21: Acanthaceae | D21: Stenandrium dulce (Cav.) Nees | E21: Stenandrium dulce | F21: (Cav.) Nees | G21: Prodr. [A. P. de Candolle] 11: 282, 1847. | H21: Hierba perenne | I21: Algarrobales, Palmares, Pastizales xerófilos, Pastizales mesófilos, Herbazales halófilos | J21: Hemicriptófita | K21: https://florauruguaya.org/taxonomias/stenandrium-dulce
A22: =VLOOKUP(especies_20260604_152756[[#This Row],[Column1]],output__33[[input_name_string]:[wfo_id2]],2,FALSE) -> wfo-0001354429 | B22: Hierba perenne | C22: Acanthaceae | D22: Thyrsacanthus sulcatus (Nees) C.Ezcurra & A.L.A.Côrtes | E22: Thyrsacanthus sulcatus | F22: (Nees) C.Ezcurra & A.L.A.Côrtes | G22: Phytotaxa 395(2): 85, 2019. | H22: Hierba perenne | I22: Algarrobales, Herbazales halófilos | K22: https://florauruguaya.org/taxonomias/thyrsacanthus-sulcatus
A23: =VLOOKUP(especies_20260604_152756[[#This Row],[Column1]],output__33[[input_name_string]:[wfo_id2]],2,FALSE) -> wfo-0000515942 | B23: Árbol | C23: Achatocarpaceae | D23: Achatocarpus praecox Griseb. | E23: Achatocarpus praecox | F23: Griseb. | G23: Abh. Königl. Ges. Wiss. Göttingen 24: 32, 1879. | H23: Árbol | I23: Algarrobales | J23: Fanerófita | K23: https://florauruguaya.org/taxonomias/achatocarpus-praecox
A24: =VLOOKUP(especies_20260604_152756[[#This Row],[Column1]],output__33[[input_name_string]:[wfo_id2]],2,FALSE) -> wfo-0000588263 | B24: Hierba perenne | C24: Aizoaceae | D24: Carpobrotus edulis (L.) N.E.Br. | E24: Carpobrotus edulis | F24: (L.) N.E.Br. | G24: Gen. S. Afr. Fl. Pl. 249, 1926. | H24: Hierba perenne | I24: Ambientes urbanos, Matorrales psamófilos, Pastizales xerófilos, Herbazales psamófilos | J24: Caméfita | K24: https://florauruguaya.org/taxonomias/carpobrotus-edulis
A25: =VLOOKUP(especies_20260604_152756[[#This Row],[Column1]],output__33[[input_name_string]:[wfo_id2]],2,FALSE) -> wfo-0000361350 | B25: Sufrútice | C25: Aizoaceae | D25: Lampranthus multiradiatus (Jacq.) N.E.Br. | E25: Lampranthus multiradiatus | F25: (Jacq.) N.E.Br. | G25: Gard. Chron. 3(87): 71, 1830. | H25: Sufrútice | I25: Herbazales psamófilos | K25: https://florauruguaya.org/taxonomias/lampranthus-multiradiatus
A26: =VLOOKUP(especies_20260604_152756[[#This Row],[Column1]],output__33[[input_name_string]:[wfo_id2]],2,FALSE) -> wfo-0001292821 | B26: Hierba perenne | C26: Aizoaceae | D26: Sesuvium sessile Pers. | E26: Sesuvium sessile | F26: Pers. | G26: Syn. Pl. [Persoon] 2(1): 39, 1806. | H26: Hierba perenne | I26: Ambientes urbanos, Herbazales halófilos | J26: Caméfita | K26: https://florauruguaya.org/taxonomias/sesuvium-sessile
A27: =VLOOKUP(especies_20260604_152756[[#This Row],[Column1]],output__33[[input_name_string]:[wfo_id2]],2,FALSE) -> wfo-0000414976 | B27: Hierba perenne | C27: Aizoaceae | D27: Tetragonia tetragonoides (Pall.) Kuntze | E27: Tetragonia tetragonoides | F27: (Pall.) Kuntze | G27: Revis. Gen. Pl. 1: 264, 1891. | H27: Hierba perenne | I27: Herbazales hidrófilos | J27: Caméfita | K27: https://florauruguaya.org/taxonomias/tetragonia-tetragonoides
A28: =VLOOKUP(especies_20260604_152756[[#This Row],[Column1]],output__33[[input_name_string]:[wfo_id2]],2,FALSE) -> wfo-0000755470 | B28: Hierba perenne | C28: Alismataceae | D28: Alisma plantago-aquatica L. | E28: Alisma plantago-aquatica | F28: L. | G28: Sp. Pl. [Linnaeus] 1: 342, 1753. | H28: Hierba perenne | I28: Dulce y salobre | K28: https://florauruguaya.org/taxonomias/alisma-plantago-aquatica
A29: =VLOOKUP(especies_20260604_152756[[#This Row],[Column1]],output__33[[input_name_string]:[wfo_id2]],2,FALSE) -> wfo-0000766394 | B29: Hierba perenne | C29: Alismataceae | D29: Echinodorus floribundus (Seub.) Seub. ex Warm. | E29: Echinodorus floribundus | F29: (Seub.) Seub. ex Warm. | G29: Vidensk. Meddel. Naturhist. Foren. Kjøbenhavn 1872: 113, 1872. | H29: Hierba perenne | I29: Herbazales hidrófilos | J29: Hemicriptófita | K29: https://florauruguaya.org/taxonomias/echinodorus-floribundus
A30: =VLOOKUP(especies_20260604_152756[[#This Row],[Column1]],output__33[[input_name_string]:[wfo_id2]],2,FALSE) -> wfo-0000766401 | B30: Hierba perenne | C30: Alismataceae | D30: Echinodorus grandiflorus (Cham. & Schltdl.) Micheli | E30: Echinodorus grandiflorus | F30: (Cham. & Schltdl.) Micheli | G30: Monogr. Phan. [A.DC. & C.DC.] 3: 57, 1881. | H30: Hierba perenne | I30: Bosques higrófilos, Algarrobales, Palmares, Herbazales hidrófilos, Dulce y salobre | J30: Hemicriptófita | K30: https://florauruguaya.org/taxonomias/echinodorus-grandiflorus
A31: =VLOOKUP(especies_20260604_152756[[#This Row],[Column1]],output__33[[input_name_string]:[wfo_id2]],2,FALSE) -> wfo-0000766423 | B31: Hierba perenne | C31: Alismataceae | D31: Echinodorus longiscapus Arechav. | E31: Echinodorus longiscapus | F31: Arechav. | G31: Anales Mus. Nac. Montevideo 4(1): 67, pl. 2, 1903. | H31: Hierba perenne | I31: Pastizales higrófilos, Herbazales hidrófilos | J31: Hemicriptófita | K31: https://florauruguaya.org/taxonomias/echinodorus-longiscapus
A32: =VLOOKUP(especies_20260604_152756[[#This Row],[Column1]],output__33[[input_name_string]:[wfo_id2]],2,FALSE) -> wfo-0000766491 | B32: Hierba perenne | C32: Alismataceae | D32: Echinodorus uruguayensis Arechav. | E32: Echinodorus uruguayensis | F32: Arechav. | G32: Anales Mus. Nac. Montevideo 4(1): 66, pl. 2, 1903. | H32: Hierba perenne | I32: Dulce y salobre | J32: Hemicriptófita | K32: https://florauruguaya.org/taxonomias/echinodorus-uruguayensis
A33: =VLOOKUP(especies_20260604_152756[[#This Row],[Column1]],output__33[[input_name_string]:[wfo_id2]],2,FALSE) -> wfo-0000834478 | B33: Hierba anual o bienal | C33: Alismataceae | D33: Helanthium tenellum (Mart. ex Schult.f.) Britton | E33: Helanthium tenellum | F33: (Mart. ex Schult.f.) Britton | G33: Man. Fl. N. States [Britton], ed. 2. 54, 1905. | H33: Hierba anual o bienal | I33: Pastizales higrófilos, Herbazales hidrófilos, Dulce y salobre | J33: Terófita | K33: https://florauruguaya.org/taxonomias/helanthium-tenellum
A34: =VLOOKUP(especies_20260604_152756[[#This Row],[Column1]],output__33[[input_name_string]:[wfo_id2]],2,FALSE) -> wfo-0000666030 | B34: Hierba perenne | C34: Alismataceae | D34: Hydrocleys nymphoides (Humb. & Bonpl. ex Willd.) Buchenau | E34: Hydrocleys nymphoides | F34: (Humb. & Bonpl. ex Willd.) Buchenau | G34: Abh. Naturwiss. Vereins Bremen 2: 2, 1871. | H34: Hierba perenne | I34: Pastizales higrófilos, Herbazales hidrófilos, Dulce y salobre | J34: Hidrófita | K34: https://florauruguaya.org/taxonomias/hydrocleys-nymphoides
A35: =VLOOKUP(especies_20260604_152756[[#This Row],[Column1]],output__33[[input_name_string]:[wfo_id2]],2,FALSE) -> wfo-0000666074 | B35: Hierba perenne | C35: Alismataceae | D35: Hydrocleys uruguayensis (Buchenau) Pedersen | E35: Hydrocleys uruguayensis | F35: (Buchenau) Pedersen | G35: Bot. Tidsskr. 57: 41, 1961. | H35: Hierba perenne | I35: Herbazales hidrófilos, Dulce y salobre | K35: https://florauruguaya.org/taxonomias/hydrocleys-uruguayensis
A36: =VLOOKUP(especies_20260604_152756[[#This Row],[Column1]],output__33[[input_name_string]:[wfo_id2]],2,FALSE) -> wfo-0000738022 | B36: Hierba perenne | C36: Alismataceae | D36: Sagittaria montevidensis Cham. & Schltdl. | E36: Sagittaria montevidensis | F36: Cham. & Schltdl. | G36: Linnaea 2: 2, 156, 1827. | H36: Hierba perenne | I36: Algarrobales, Herbazales hidrófilos, Dulce y salobre | J36: Hidrófita | K36: https://florauruguaya.org/taxonomias/sagittaria-montevidensis
A37: =VLOOKUP(especies_20260604_152756[[#This Row],[Column1]],output__33[[input_name_string]:[wfo_id2]],2,FALSE) -> wfo-0000759175 | B37: Hierba perenne | C37: Alstroemeriaceae | D37: Alstroemeria isabellana Herb. | E37: Alstroemeria isabellana | F37: Herb. | G37: Amaryllidaceae 88, t. 6, f. 4-6, 1837. | H37: Hierba perenne | I37: Bosques higrófilos, Pastizales higrófilos | J37: Hemicriptófita | K37: https://florauruguaya.org/taxonomias/alstroemeria-isabellana
A38: =VLOOKUP(especies_20260604_152756[[#This Row],[Column1]],output__33[[input_name_string]:[wfo_id2]],2,FALSE) -> wfo-0000759283 | B38: Hierba perenne | C38: Alstroemeriaceae | D38: Alstroemeria psittacina Lehm. | E38: Alstroemeria psittacina | F38: Lehm. | G38: Sem. Hort. Bot. Hamburg. 1826: 17, 1826. | H38: Hierba perenne | I38: Bosques ribereños | J38: Hemicriptófita | K38: https://florauruguaya.org/taxonomias/alstroemeria-psittacina
A39: =VLOOKUP(especies_20260604_152756[[#This Row],[Column1]],output__33[[input_name_string]:[wfo_id2]],2,FALSE) -> wfo-0000528632 | B39: Hierba perenne | C39: Amaranthaceae | D39: Alternanthera kurtzii Schinz ex Pedersen | E39: Alternanthera kurtzii | F39: Schinz ex Pedersen | G39: Darwiniana 14(2-3): 435, 1967. | H39: Hierba perenne | I39: Bosques ribereños, Algarrobales, Pastizales higrófilos | K39: https://florauruguaya.org/taxonomias/alternanthera-kurtzii
A40: =VLOOKUP(especies_20260604_152756[[#This Row],[Column1]],output__33[[input_name_string]:[wfo_id2]],2,FALSE) -> wfo-0000528686 | B40: Hierba perenne | C40: Amaranthaceae | D40: Alternanthera micrantha R.E.Fr. | E40: Alternanthera micrantha | F40: R.E.Fr. | G40: Ark. Bot. 16(12): 14, 1920. | H40: Hierba perenne | I40: Bosques ribereños | J40: Caméfita | K40: https://florauruguaya.org/taxonomias/alternanthera-micrantha
...

Sheet especies_20260407_163427
A1: Column1 | B1: Column2 | C1: Column3 | D1: Column4 | E1: Column5 | F1: Column6 | G1: Column7 | H1: Column8
A2: Familia | B2: Nombre | C2: Autor | D2: Pub. | E2: Hábito | F2: Formaciones vegetales | G2: Forma de vida | H2: Link stand alone
A3: Acanthaceae | B3: Dicliptera squarrosa | C3: Nees | D3: Fl. Bras. [Martius] 9: 161, 1847. | E3: Sufrútice | F3: Bosques ribereños, Algarrobales, Matorrales mesófilos, Matorrales psamófilos, Pastizales xerófilos | G3: Caméfita | H3: https://florauruguaya.org/taxonomias/dicliptera-squarrosa
A4: Acanthaceae | B4: Dyschoriste humilis | C4: (Nees) Lindau | D4: Bot. Jahrb. Syst. 19(4): 15, 1894. | E4: Hierba perenne | F4: Algarrobales, Matorrales xerófilos, Pastizales xerófilos | G4: Caméfita | H4: https://florauruguaya.org/taxonomias/dyschoriste-humilis
A5: Acanthaceae | B5: Dyschoriste hygrophiloides | C5: (Nees) Kuntze | D5: Revis. Gen. Pl. 2: 486, 1891. | E5: Hierba perenne | F5: Pastizales xerófilos, Pastizales mesófilos | H5: https://florauruguaya.org/taxonomias/dyschoriste-hygrophiloides
A6: Acanthaceae | B6: Hygrophila costata | C6: Nees & T.Nees | D6: Pl. Hort. Bonn. Icon. 7, t. 3, 1824. | E6: Hierba perenne | F6: Bosques ribereños, Bosques higrófilos, Algarrobales, Palmares, Herbazales hidrófilos | G6: Caméfita | H6: https://florauruguaya.org/taxonomias/hygrophila-costata
A7: Acanthaceae | B7: Hygrophila guianensis | C7: Nees | D7: London J. Bot. 4: 634, 1845. | E7: Hierba perenne | F7: Bosques ribereños | H7: https://florauruguaya.org/taxonomias/hygrophila-guianensis
A8: Acanthaceae | B8: Justicia axillaris | C8: (Nees) Lindau | D8: Nat. Pflanzenfam. [Engler & Prantl] 4(3b): 350, 1895. | E8: Hierba perenne | F8: Matorrales xerófilos, Pastizales xerófilos | H8: https://florauruguaya.org/taxonomias/justicia-axillaris
A9: Acanthaceae | B9: Justicia brasiliana | C9: Roth | D9: Nov. Pl. Sp. 17, 1821. | E9: Sufrútice | F9: Bosques de quebradas, Bosques ribereños | G9: Caméfita | H9: https://florauruguaya.org/taxonomias/justicia-brasiliana
A10: Acanthaceae | B10: Justicia comata | C10: (L.) Lam. | D10: Encycl. [J. Lamarck & al.] 1(2): 632, 1785. | E10: Hierba perenne | F10: Bosques ribereños, Herbazales hidrófilos | G10: Caméfita | H10: https://florauruguaya.org/taxonomias/justicia-comata
A11: Acanthaceae | B11: Justicia laevilinguis | C11: (Nees) Lindau | D11: Bot. Jahrb. Syst. 19(4): 20, 1894. | E11: Hierba perenne | F11: Algarrobales, Pastizales higrófilos, Herbazales hidrófilos | G11: Caméfita | H11: https://florauruguaya.org/taxonomias/justicia-laevilinguis
A12: Acanthaceae | B12: Justicia oblonga | C12: (Nees) Lindau | D12: Nat. Pflanzenfam. [Engler & Prantl] 4(3b): 350, 1895. | E12: Hierba perenne | F12: Bosques ribereños | H12: https://florauruguaya.org/taxonomias/justicia-oblonga
A13: Acanthaceae | B13: Justicia polygaloides | C13: (S.Moore) Lindau | D13: Bull. Herb. Boissier 2(3): 633, 1933. | E13: Hierba perenne | F13: Pastizales higrófilos | H13: https://florauruguaya.org/taxonomias/justicia-polygaloides
A14: Acanthaceae | B14: Justicia tweedieana | C14: (Nees) Griseb. | D14: Abh. Königl. Ges. Wiss. Göttingen 19: 225, 1874. | E14: Arbusto | F14: Algarrobales, Pastizales xerófilos, Herbazales halófilos | G14: Nanofanerófita | H14: https://florauruguaya.org/taxonomias/justicia-tweedieana
A15: Acanthaceae | B15: Poikilacanthus glandulosus | C15: (Nees) Ariza | D15: Kurtziana 17: 159, 1984. | E15: Arbusto | F15: Bosques ribereños, Matorrales mesófilos | G15: Nanofanerófita | H15: https://florauruguaya.org/taxonomias/poikilacanthus-glandulosus
A16: Acanthaceae | B16: Ruellia angustiflora | C16: (Nees) Lindau ex Rambo | D16: Iheringia, Bot. 12: 23, 1964. | E16: Arbusto | F16: Bosques de quebradas | G16: Nanofanerófita | H16: https://florauruguaya.org/taxonomias/ruellia-angustiflora
A17: Acanthaceae | B17: Ruellia hygrophila | C17: Mart. | D17: Flora 24(2): 65, 1841. | E17: Hierba perenne | F17: Matorrales xerófilos, Herbazales hidrófilos | G17: Hemicriptófita | H17: https://florauruguaya.org/taxonomias/ruellia-hygrophila
A18: Acanthaceae | B18: Ruellia hypericoides | C18: (Nees) Lindau | D18: Bot. Jahrb. Syst. 19(4): 16, 1894. | E18: Hierba perenne | F18: Pastizales xerófilos | G18: Hemicriptófita | H18: https://florauruguaya.org/taxonomias/ruellia-hypericoides
A19: Acanthaceae | B19: Ruellia morongii | C19: Britton | D19: Ann. New York Acad. Sci. 7: 192, 1893. | E19: Hierba perenne | F19: Pastizales xerófilos, Pastizales mesófilos | G19: Hemicriptófita | H19: https://florauruguaya.org/taxonomias/ruellia-morongii
A20: Acanthaceae | B20: Ruellia simplex | C20: C.Wright | D20: Anales Acad. Ci. Méd. Habana 6(41): 321, 1870. | E20: Hierba perenne | F20: Bosques ribereños, Algarrobales, Pastizales higrófilos, Herbazales halófilos | G20: Caméfita | H20: https://florauruguaya.org/taxonomias/ruellia-simplex
A21: Acanthaceae | B21: Stenandrium diphyllum | C21: Nees | D21: Fl. Bras. [Martius] 9: 75, 1847. | E21: Hierba perenne | F21: Matorrales xerófilos, Pastizales xerófilos | G21: Hemicriptófita | H21: https://florauruguaya.org/taxonomias/stenandrium-diphyllum
A22: Acanthaceae | B22: Stenandrium dulce | C22: (Cav.) Nees | D22: Prodr. [A. P. de Candolle] 11: 282, 1847. | E22: Hierba perenne | F22: Algarrobales, Palmares, Pastizales xerófilos, Pastizales mesófilos, Herbazales halófilos | G22: Hemicriptófita | H22: https://florauruguaya.org/taxonomias/stenandrium-dulce
A23: Acanthaceae | B23: Thyrsacanthus sulcatus | C23: (Nees) C.Ezcurra & A.L.A.Côrtes | D23: Phytotaxa 395(2): 85, 2019. | E23: Hierba perenne | F23: Algarrobales, Herbazales halófilos | H23: https://florauruguaya.org/taxonomias/thyrsacanthus-sulcatus
A24: Achatocarpaceae | B24: Achatocarpus praecox | C24: Griseb. | D24: Abh. Königl. Ges. Wiss. Göttingen 24: 32, 1879. | E24: Árbol | F24: Algarrobales | G24: Fanerófita | H24: https://florauruguaya.org/taxonomias/achatocarpus-praecox
A25: Aizoaceae | B25: Carpobrotus edulis | C25: (L.) N.E.Br. | D25: Gen. S. Afr. Fl. Pl. 249, 1926. | E25: Hierba perenne | F25: Ambientes urbanos, Matorrales psamófilos, Pastizales xerófilos, Herbazales psamófilos | G25: Caméfita | H25: https://florauruguaya.org/taxonomias/carpobrotus-edulis
A26: Aizoaceae | B26: Lampranthus multiradiatus | C26: (Jacq.) N.E.Br. | D26: Gard. Chron. 3(87): 71, 1830. | E26: Sufrútice | F26: Herbazales psamófilos | H26: https://florauruguaya.org/taxonomias/lampranthus-multiradiatus
A27: Aizoaceae | B27: Sesuvium sessile | C27: Pers. | D27: Syn. Pl. [Persoon] 2(1): 39, 1806. | E27: Hierba perenne | F27: Ambientes urbanos, Herbazales halófilos | G27: Caméfita | H27: https://florauruguaya.org/taxonomias/sesuvium-sessile
A28: Aizoaceae | B28: Tetragonia tetragonoides | C28: (Pall.) Kuntze | D28: Revis. Gen. Pl. 1: 264, 1891. | E28: Hierba perenne | F28: Herbazales hidrófilos | G28: Caméfita | H28: https://florauruguaya.org/taxonomias/tetragonia-tetragonoides
A29: Alismataceae | B29: Alisma plantago-aquatica | C29: L. | D29: Sp. Pl. [Linnaeus] 1: 342, 1753. | E29: Hierba perenne | F29: Dulce y salobre | H29: https://florauruguaya.org/taxonomias/alisma-plantago-aquatica
A30: Alismataceae | B30: Echinodorus floribundus | C30: (Seub.) Seub. ex Warm. | D30: Vidensk. Meddel. Naturhist. Foren. Kjøbenhavn 1872: 113, 1872. | E30: Hierba perenne | F30: Herbazales hidrófilos | G30: Hemicriptófita | H30: https://florauruguaya.org/taxonomias/echinodorus-floribundus
A31: Alismataceae | B31: Echinodorus grandiflorus | C31: (Cham. & Schltdl.) Micheli | D31: Monogr. Phan. [A.DC. & C.DC.] 3: 57, 1881. | E31: Hierba perenne | F31: Bosques higrófilos, Algarrobales, Palmares, Herbazales hidrófilos, Dulce y salobre | G31: Hemicriptófita | H31: https://florauruguaya.org/taxonomias/echinodorus-grandiflorus
A32: Alismataceae | B32: Echinodorus longiscapus | C32: Arechav. | D32: Anales Mus. Nac. Montevideo 4(1): 67, pl. 2, 1903. | E32: Hierba perenne | F32: Pastizales higrófilos, Herbazales hidrófilos | G32: Hemicriptófita | H32: https://florauruguaya.org/taxonomias/echinodorus-longiscapus
A33: Alismataceae | B33: Echinodorus uruguayensis | C33: Arechav. | D33: Anales Mus. Nac. Montevideo 4(1): 66, pl. 2, 1903. | E33: Hierba perenne | F33: Dulce y salobre | G33: Hemicriptófita | H33: https://florauruguaya.org/taxonomias/echinodorus-uruguayensis
A34: Alismataceae | B34: Helanthium tenellum | C34: (Mart. ex Schult.f.) Britton | D34: Man. Fl. N. States [Britton], ed. 2. 54, 1905. | E34: Hierba anual o bienal | F34: Pastizales higrófilos, Herbazales hidrófilos, Dulce y salobre | G34: Terófita | H34: https://florauruguaya.org/taxonomias/helanthium-tenellum
A35: Alismataceae | B35: Hydrocleys nymphoides | C35: (Humb. & Bonpl. ex Willd.) Buchenau | D35: Abh. Naturwiss. Vereins Bremen 2: 2, 1871. | E35: Hierba perenne | F35: Pastizales higrófilos, Herbazales hidrófilos, Dulce y salobre | G35: Hidrófita | H35: https://florauruguaya.org/taxonomias/hydrocleys-nymphoides
A36: Alismataceae | B36: Hydrocleys uruguayensis | C36: (Buchenau) Pedersen | D36: Bot. Tidsskr. 57: 41, 1961. | E36: Hierba perenne | F36: Herbazales hidrófilos, Dulce y salobre | H36: https://florauruguaya.org/taxonomias/hydrocleys-uruguayensis
A37: Alismataceae | B37: Sagittaria montevidensis | C37: Cham. & Schltdl. | D37: Linnaea 2: 2, 156, 1827. | E37: Hierba perenne | F37: Algarrobales, Herbazales hidrófilos, Dulce y salobre | G37: Hidrófita | H37: https://florauruguaya.org/taxonomias/sagittaria-montevidensis
A38: Alstroemeriaceae | B38: Alstroemeria isabellana | C38: Herb. | D38: Amaryllidaceae 88, t. 6, f. 4-6, 1837. | E38: Hierba perenne | F38: Bosques higrófilos, Pastizales higrófilos | G38: Hemicriptófita | H38: https://florauruguaya.org/taxonomias/alstroemeria-isabellana
A39: Alstroemeriaceae | B39: Alstroemeria psittacina | C39: Lehm. | D39: Sem. Hort. Bot. Hamburg. 1826: 17, 1826. | E39: Hierba perenne | F39: Bosques ribereños | G39: Hemicriptófita | H39: https://florauruguaya.org/taxonomias/alstroemeria-psittacina
A40: Amaranthaceae | B40: Alternanthera kurtzii | C40: Schinz ex Pedersen | D40: Darwiniana 14(2-3): 435, 1967. | E40: Hierba perenne | F40: Bosques ribereños, Algarrobales, Pastizales higrófilos | H40: https://florauruguaya.org/taxonomias/alternanthera-kurtzii
...

Sheet candidates (3)
A1: score | B1: wfo_id | C1: wfo_full_name | D1: wfo_check | E1: input_name_string | F1: wfo_id | G1: wfo_full_name
A2: 2 | B2: wfo-0000658310 | C2: Dyschoriste humilis Lindau | D2: unplaced | E2: Dyschoriste humilis (Nees) Lindau | F2: wfo-0000658310 | G2: Dyschoriste humilis Lindau
A3: 1 | B3: wfo-1200030165 | C3: Dyschoriste humilis Lindau | D3: Code/Plantae/Pteridobiotina/Angiosperms/Lamiales/Acanthaceae/Dyschoriste/humilis | E3: Dyschoriste humilis (Nees) Lindau | F3: wfo-1200030165 | G3: Dyschoriste humilis Lindau
A4: 1 | B4: wfo-0000726781 | C4: Hygrophila costata Nees | D4: Code/Plantae/Pteridobiotina/Angiosperms/Lamiales/Acanthaceae/Hygrophila/costata | E4: Hygrophila costata Nees & T.Nees | F4: wfo-0000726781 | G4: Hygrophila costata Nees
A5: 1 | B5: wfo-0000766394 | C5: Echinodorus floribundus Seub. ex Warm. | D5: Code/Plantae/Pteridobiotina/Angiosperms/Alismatales/Alismataceae/Aquarius/floribundus$Echinodorus/floribundus | E5: Echinodorus floribundus (Seub.) Seub. ex Warm. | F5: wfo-0000766394 | G5: Echinodorus floribundus Seub. ex Warm.
A6: 2 | B6: wfo-0000530163 | C6: Amaranthus crispus (Lesp. & Thévenau) A.Braun ex J.M.Coult. & S.Watson | D6: Code/Plantae/Pteridobiotina/Angiosperms/Caryophyllales/Amaranthaceae/Amarantheae/Amaranthus/crispus | E6: Amaranthus crispus (Lesp. & Thévenau) A.Braun ex S.Watson & J.M.Coult. | F6: wfo-0000530163 | G6: Amaranthus crispus (Lesp. & Thévenau) A.Braun ex J.M.Coult. & S.Watson
A7: 1 | B7: wfo-0001046238 | C7: Amaranthus crispus Terrac. | D7: unplaced | E7: Amaranthus crispus (Lesp. & Thévenau) A.Braun ex S.Watson & J.M.Coult. | F7: wfo-0001046238 | G7: Amaranthus crispus Terrac.
A8: 1 | B8: wfo-0000743782 | C8: Dysphania bonariensis (Hook.f.) Mosyakin & Clemants | D8: Code/Plantae/Pteridobiotina/Angiosperms/Caryophyllales/Chenopodiaceae/Chenopodioideae/Atripliceae/Chenopodium/haumanii$Dysphania/bonariensis | E8: Dysphania bonariensis (Hook.f.) Mosyakin & Clemants ex Sukhor. | F8: wfo-0000743782 | G8: Dysphania bonariensis (Hook.f.) Mosyakin & Clemants
A9: 1 | B9: wfo-1000085903 | C9: Holmbergia tweediei Speg. | D9: unplaced | E9: Holmbergia tweediei (Moq.) Speg. | F9: wfo-1000085903 | G9: Holmbergia tweediei Speg.
A10: 1 | B10: wfo-0000661874 | C10: Hippeastrum vittatum (L'Hér.) Herb. | D10: Code/Plantae/Pteridobiotina/Angiosperms/Asparagales/Amaryllidaceae/Hippeastrum/vittatum | E10: Hippeastrum vittatum (L&#39;Hér.) Herb. | F10: wfo-0000661874 | G10: Hippeastrum vittatum (L'Hér.) Herb.
A11: 1 | B11: wfo-0000752531 | C11: Zephyranthes brachyandra (Baker) Backer & Beknopte | D11: Code/Plantae/Pteridobiotina/Angiosperms/Asparagales/Amaryllidaceae/Habranthus/brachyandrus$Zephyranthes/brachyandra | E11: Zephyranthes brachyandra (Baker) Backer | F11: wfo-0000752531 | G11: Zephyranthes brachyandra (Baker) Backer & Beknopte
A12: 1 | B12: wfo-0000753709 | C12: Zephyranthes caerulea Baker | D12: Code/Plantae/Pteridobiotina/Angiosperms/Asparagales/Amaryllidaceae/Habranthus/caeruleus$Zephyranthes/caerulea | E12: Zephyranthes caerulea (Griseb.) Baker | F12: wfo-0000753709 | G12: Zephyranthes caerulea Baker
A13: 1 | B13: wfo-0000752452 | C13: Zephyranthes mesochloa Herb. | D13: Code/Plantae/Pteridobiotina/Angiosperms/Asparagales/Amaryllidaceae/Zephyranthes/mesochloa | E13: Zephyranthes mesochloa Herb. in Lindl. | F13: wfo-0000752452 | G13: Zephyranthes mesochloa Herb.
... A582: 1 | B582: wfo-0001146331 | C582: Porlieria microphylla (Baill.) Descole, O'Donell & Lourteig | D582: Code/Plantae/Pteridobiotina/Angiosperms/Zygophyllales/Zygophyllaceae/Porlieria/microphylla | E582: Porlieria microphylla (Baill.) Descole, O&#39;Donell & Lourteig | F582: wfo-0001146331 | G582: Porlieria microphylla (Baill.) Descole, O'Donell & Lourteig

Sheet output (33)
A1: wfo_id | B1: wfo_full_name | C1: wfo_check | D1: input_name_string | E1: wfo_id2
A2: wfo-0000646051 | B2: Dicliptera squarrosa Nees | C2: Code/Plantae/Pteridobiotina/Angiosperms/Lamiales/Acanthaceae/Dicliptera/squarrosa | D2: Dicliptera squarrosa Nees | E2: wfo-0000646051
A3: wfo-1200030165 | B3: Dyschoriste humilis (Nees) Lindau | C3: 2 candidates found. | D3: Dyschoriste humilis (Nees) Lindau | E3: wfo-1200030165
A4: wfo-0000658315 | B4: Dyschoriste hygrophiloides (Nees) Kuntze | C4: Code/Plantae/Pteridobiotina/Angiosperms/Lamiales/Acanthaceae/Dyschoriste/hygrophiloides | D4: Dyschoriste hygrophiloides (Nees) Kuntze | E4: wfo-0000658315
A5: wfo-0000726781 | B5: Hygrophila costata Nees | C5: 1 candidates found. | D5: Hygrophila costata Nees & T.Nees | E5: wfo-0000726781
A6: wfo-0000726797 | B6: Hygrophila guianensis Nees | C6: Code/Plantae/Pteridobiotina/Angiosperms/Lamiales/Acanthaceae/Hygrophila/guianensis | D6: Hygrophila guianensis Nees | E6: wfo-0000726797
A7: wfo-0001043972 | B7: Justicia axillaris (Nees) Lindau | C7: Code/Plantae/Pteridobiotina/Angiosperms/Lamiales/Acanthaceae/Justicia/axillaris | D7: Justicia axillaris (Nees) Lindau | E7: wfo-0001043972
A8: wfo-0000354192 | B8: Justicia brasiliana Roth | C8: Code/Plantae/Pteridobiotina/Angiosperms/Lamiales/Acanthaceae/Justicia/brasiliana | D8: Justicia brasiliana Roth | E8: wfo-0000354192
A9: wfo-0000354453 | B9: Justicia comata (L.) Lam. | C9: Code/Plantae/Pteridobiotina/Angiosperms/Lamiales/Acanthaceae/Dianthera/comata$Justicia/comata | D9: Justicia comata (L.) Lam. | E9: wfo-0000354453
A10: wfo-0000355947 | B10: Justicia laevilinguis (Nees) Lindau | C10: Code/Plantae/Pteridobiotina/Angiosperms/Lamiales/Acanthaceae/Dianthera/laevilinguis$Justicia/laevilinguis | D10: Justicia laevilinguis (Nees) Lindau | E10: wfo-0000355947
A11: wfo-0001044021 | B11: Justicia oblonga (Nees) Lindau | C11: Code/Plantae/Pteridobiotina/Angiosperms/Lamiales/Acanthaceae/Dianthera/oblonga$Justicia/oblonga | D11: Justicia oblonga (Nees) Lindau | E11: wfo-0001044021
A12: wfo-0001044033 | B12: Justicia polygaloides (S.Moore) Lindau | C12: Code/Plantae/Pteridobiotina/Angiosperms/Lamiales/Acanthaceae/Dianthera/polygaloides$Justicia/polygaloides | D12: Justicia polygaloides (S.Moore) Lindau | E12: wfo-0001044033
... A315: wfo-0000574288 | B315: Tillandsia arequitae (André) André ex Mez | C315: Code/Plantae/Pteridobiotina/Angiosperms/Poales/Bromeliaceae/Tillandsia/arequitae | D315: Tillandsia arequitae (André) André ex Mez | E315: wfo-0000574288
A316: wfo-0000573817 | C316: 1 candidates found. | D316: Tillandsia aëranthos (Loisel.) L.B.Sm. | E316: wfo-0000573817
A317: wfo-0000574723 | B317: Tillandsia bandensis Baker | C317: Code/Plantae/Pteridobiotina/Angiosperms/Poales/Bromeliaceae/Tillandsia/bandensis | D317: Tillandsia bandensis Baker | E317: wfo-0000574723
A318: wfo-0000575760 | B318: Tillandsia capillaris Ruiz & Pav. | C318: Code/Plantae/Pteridobiotina/Angiosperms/Poales/Bromeliaceae/Tillandsia/capillaris | D318: Tillandsia capillaris Ruiz & Pav. | E318: wfo-0000575760
A319: wfo-1000090353 | B319: Tillandsia cleistopetala Rossado | C319: unplaced | D319: Tillandsia cleistopetala Rossado | E319: wfo-1000090353
A320: wfo-0000577840 | B320: Tillandsia duratii Vis. | C320: Code/Plantae/Pteridobiotina/Angiosperms/Poales/Bromeliaceae/Tillandsia/duratii | D320: Tillandsia duratii Vis. | E320: wfo-0000577840
A321: wfo-0000578751 | B321: Tillandsia geminiflora Brongn. | C321: Code/Plantae/Pteridobiotina/Angiosperms/Poales/Bromeliaceae/Tillandsia/geminiflora | D321: Tillandsia geminiflora Brongn. | E321: wfo-0000578751
A322: wfo-0000580176 | B322: Tillandsia ixioides Griseb. | C322: Code/Plantae/Pteridobiotina/Angiosperms/Poales/Bromeliaceae/Tillandsia/ixioides | D322: Tillandsia ixioides Griseb. | E322: wfo-0000580176
A323: wfo-0000580809 | B323: Tillandsia loliacea Mart. ex Schult. & Schult.f. | C323: Code/Plantae/Pteridobiotina/Angiosperms/Poales/Bromeliaceae/Tillandsia/loliacea | D323: Tillandsia loliacea Mart. ex Schult. & Schult.f. | E323: wfo-0000580809
A324: wfo-0000583812 | B324: Tillandsia recurvata (L.) L. | C324: Code/Plantae/Pteridobiotina/Angiosperms/Poales/Bromeliaceae/Tillandsia/recurvata | D324: Tillandsia recurvata (L.) L. | E324: wfo-0000583812
A325: wfo-0000583868 | B325: Tillandsia recurvifolia Hook. | C325: Code/Plantae/Pteridobiotina/Angiosperms/Poales/Bromeliaceae/Tillandsia/recurvifolia | D325: Tillandsia recurvifolia Hook. | E325: wfo-0000583868
A326: wfo-0000585601 | B326: Tillandsia stricta Sol. ex Ker Gawl. | C326: Code/Plantae/Pteridobiotina/Angiosperms/Poales/Bromeliaceae/Tillandsia/stricta | D326: Tillandsia stricta Sol. ex Ker Gawl. | E326: wfo-0000585601
A327: wfo-0000585931 | B327: Tillandsia tricholepis Baker | C327: Code/Plantae/Pteridobiotina/Angiosperms/Poales/Bromeliaceae/Tillandsia/tricholepis | D327: Tillandsia tricholepis Baker | E327: wfo-0000585931
A328: wfo-1000007958 | B328: Tillandsia uruguayensis Rossado | C328: Code/Plantae/Pteridobiotina/Angiosperms/Poales/Bromeliaceae/Tillandsia/uruguayensis | D328: Tillandsia uruguayensis Rossado | E328: wfo-1000007958
... A341: wfo-0000691765 | B341: Frailea phaeodisca (Speg.) Backeb. & F.M.Knuth | C341: Code/Plantae/Pteridobiotina/Angiosperms/Caryophyllales/Cactaceae/Frailea/phaeodisca | D341: Frailea phaeodisca (Speg.) Backeb. & F.M.Knuth | E341: wfo-0000691765
A342: =VLOOKUP(output__33[[#This Row],[input_name_string]],'candidates (3)'!E$2:G$582,2,FALSE) -> wfo-0000691773 | B342: =VLOOKUP(output__33[[#This Row],[input_name_string]],'candidates (3)'!E$2:G$582,3,FALSE) -> Frailea pumila (Lem.) Britton & Rose | C342: 1 candidates found. | D342: Frailea pumila Britton & Rose | E342: wfo-0000691773
A343: =VLOOKUP(output__33[[#This Row],[input_name_string]],'candidates (3)'!E$2:G$582,2,FALSE) -> wfo-0000691782 | B343: =VLOOKUP(output__33[[#This Row],[input_name_string]],'candidates (3)'!E$2:G$582,3,FALSE) -> Frailea pygmaea (Speg.) Britton & Rose | C343: 1 candidates found. | D343: Frailea pygmaea Britton & Rose | E343: wfo-0000691782
A344: =VLOOKUP(output__33[[#This Row],[input_name_string]],'candidates (3)'!E$2:G$582,2,FALSE) -> wfo-0000691803 | B344: =VLOOKUP(output__33[[#This Row],[input_name_string]],'candidates (3)'!E$2:G$582,3,FALSE) -> Frailea schilinzkyana (F.Haage) Britton & Rose | C344: 1 candidates found. | D344: Frailea schilinzkyana (F.Haage & K.Schum.) Britton & Rose | E344: wfo-0000691803
A345: wfo-0000712444 | B345: Gymnocalycium denudatum (Link & Otto) Pfeiff. ex Mittler | C345: Code/Plantae/Pteridobiotina/Angiosperms/Caryophyllales/Cactaceae/Gymnocalycium/denudatum | D345: Gymnocalycium denudatum (Link & Otto) Pfeiff. ex Mittler | E345: wfo-0000712444
A346: =VLOOKUP(output__33[[#This Row],[input_name_string]],'candidates (3)'!E$2:G$582,2,FALSE) -> wfo-0000712493 | B346: =VLOOKUP(output__33[[#This Row],[input_name_string]],'candidates (3)'!E$2:G$582,3,FALSE) -> Gymnocalycium hyptiacanthum (Lem.) Britton & Rose | C346: 1 candidates found. | D346: Gymnocalycium hyptiacanthum Britton & Rose | E346: wfo-0000712493
A347: wfo-0000712674 | B347: Gymnocalycium schroederianum Osten | C347: Code/Plantae/Pteridobiotina/Angiosperms/Caryophyllales/Cactaceae/Gymnocalycium/schroederianum | D347: Gymnocalycium schroederianum Osten | E347: wfo-0000712674
A348: wfo-0000715881 | B348: Harrisia bonplandii (Parm. ex Pfeiff.) Britton & Rose | C348: Code/Plantae/Pteridobiotina/Angiosperms/Caryophyllales/Cactaceae/Harrisia/bonplandii | D348: Harrisia bonplandii (Parm. ex Pfeiff.) Britton & Rose | E348: wfo-0000715881
A349: wfo-0001287227 | B349: Harrisia martinii (Labour.) Britton | C349: Code/Plantae/Pteridobiotina/Angiosperms/Caryophyllales/Cactaceae/Harrisia/martinii | D349: Harrisia martinii (Labour.) Britton | E349: wfo-0001287227
A350: wfo-0001289289 | B350: Harrisia pomanensis (F.A.C.Weber ex K.Schum.) Britton & Rose | C350: Code/Plantae/Pteridobiotina/Angiosperms/Caryophyllales/Cactaceae/Harrisia/pomanensis | D350: Harrisia pomanensis (F.A.C.Weber ex K.Schum.) Britton & Rose | E350: wfo-0001289289
A351: wfo-0001239324 | B351: Lepismium aculeatum (F.A.C.Weber) Barthlott | C351: Code/Plantae/Pteridobiotina/Angiosperms/Caryophyllales/Cactaceae/Lepismium/lumbricoides/aculeatum$Lepismium/aculeatum | D351: Lepismium aculeatum (F.A.C.Weber) Barthlott | E351: wfo-0001239324
A352: wfo-0000357990 | B352: Lepismium cruciforme (Vell.) Miq. | C352: Code/Plantae/Pteridobiotina/Angiosperms/Caryophyllales/Cactaceae/Lepismium/cruciforme | D352: Lepismium cruciforme (Vell.) Miq. | E352: wfo-0000357990
A353: wfo-0000357993 | B353: Lepismium lumbricoides (Lem.) Barthlott | C353: Code/Plantae/Pteridobiotina/Angiosperms/Caryophyllales/Cactaceae/Lepismium/lumbricoides | D353: Lepismium lumbricoides (Lem.) Barthlott | E353: wfo-0000357993
A354: wfo-0001433069 | B354: Opuntia arechavaletae Speg. | C354: Code/Plantae/Pteridobiotina/Angiosperms/Caryophyllales/Cactaceae/Opuntia/arechavaletae | D354: Opuntia arechavaletae Speg. | E354: wfo-0001433069
...

Sheet florauruguaya_V_4_habit
A1: wfo_ID | B1: Hábito | C1: Familia | D1: Column1 | E1: Nombre | F1: Autor | G1: Pub. | H1: BibliographicCitation | I1: url
A2: =VLOOKUP(especies_20260604_1527564[[#This Row],[Column1]],output__33[[input_name_string]:[wfo_id2]],2,FALSE) -> wfo-0000646051 | B2: Sufrútice | C2: Acanthaceae | D2: Dicliptera squarrosa Nees | E2: Dicliptera squarrosa | F2: Nees | G2: Fl. Bras. [Martius] 9: 161, 1847. | H2: Marchesi, E., Mailhos, A., & Bonifacino, J. M. (2026). Flora Uruguaya: Flora Vascular del Uruguay. ISSN 3121-2050, V. 1.3. [Data set]. Zenodo. https://doi.org/10.5281/zenodo.20547117 | I2: https://florauruguaya.org/taxonomias/dicliptera-squarrosa
A3: =VLOOKUP(especies_20260604_1527564[[#This Row],[Column1]],output__33[[input_name_string]:[wfo_id2]],2,FALSE) -> wfo-1200030165 | B3: Hierba perenne | C3: Acanthaceae | D3: Dyschoriste humilis (Nees) Lindau | E3: Dyschoriste humilis | F3: (Nees) Lindau | G3: Bot. Jahrb. Syst. 19(4): 15, 1894. | H3: Marchesi, E., Mailhos, A., & Bonifacino, J. M. (2026). Flora Uruguaya: Flora Vascular del Uruguay. ISSN 3121-2050, V. 1.3. [Data set]. Zenodo. https://doi.org/10.5281/zenodo.20547117 | I3: https://florauruguaya.org/taxonomias/dyschoriste-humilis
A4: =VLOOKUP(especies_20260604_1527564[[#This Row],[Column1]],output__33[[input_name_string]:[wfo_id2]],2,FALSE) -> wfo-0000658315 | B4: Hierba perenne | C4: Acanthaceae | D4: Dyschoriste hygrophiloides (Nees) Kuntze | E4: Dyschoriste hygrophiloides | F4: (Nees) Kuntze | G4: Revis. Gen. Pl. 2: 486, 1891. | H4: Marchesi, E., Mailhos, A., & Bonifacino, J. M. (2026). Flora Uruguaya: Flora Vascular del Uruguay. ISSN 3121-2050, V. 1.3. [Data set]. Zenodo. https://doi.org/10.5281/zenodo.20547117 | I4: https://florauruguaya.org/taxonomias/dyschoriste-hygrophiloides
A5: =VLOOKUP(especies_20260604_1527564[[#This Row],[Column1]],output__33[[input_name_string]:[wfo_id2]],2,FALSE) -> wfo-0000726781 | B5: Hierba perenne | C5: Acanthaceae | D5: Hygrophila costata Nees & T.Nees | E5: Hygrophila costata | F5: Nees & T.Nees | G5: Pl. Hort. Bonn. Icon. 7, t. 3, 1824. | H5: Marchesi, E., Mailhos, A., & Bonifacino, J. M. (2026). Flora Uruguaya: Flora Vascular del Uruguay. ISSN 3121-2050, V. 1.3. [Data set]. Zenodo. https://doi.org/10.5281/zenodo.20547117 | I5: https://florauruguaya.org/taxonomias/hygrophila-costata
A6: =VLOOKUP(especies_20260604_1527564[[#This Row],[Column1]],output__33[[input_name_string]:[wfo_id2]],2,FALSE) -> wfo-0000726797 | B6: Hierba perenne | C6: Acanthaceae | D6: Hygrophila guianensis Nees | E6: Hygrophila guianensis | F6: Nees | G6: London J. Bot. 4: 634, 1845. | H6: Marchesi, E., Mailhos, A., & Bonifacino, J. M. (2026). Flora Uruguaya: Flora Vascular del Uruguay. ISSN 3121-2050, V. 1.3. [Data set]. Zenodo. https://doi.org/10.5281/zenodo.20547117 | I6: https://florauruguaya.org/taxonomias/hygrophila-guianensis
A7: =VLOOKUP(especies_20260604_1527564[[#This Row],[Column1]],output__33[[input_name_string]:[wfo_id2]],2,FALSE) -> wfo-0001043972 | B7: Hierba perenne | C7: Acanthaceae | D7: Justicia axillaris (Nees) Lindau | E7: Justicia axillaris | F7: (Nees) Lindau | G7: Nat. Pflanzenfam. [Engler & Prantl] 4(3b): 350, 1895. | H7: Marchesi, E., Mailhos, A., & Bonifacino, J. M. (2026). Flora Uruguaya: Flora Vascular del Uruguay. ISSN 3121-2050, V. 1.3. [Data set]. Zenodo. https://doi.org/10.5281/zenodo.20547117 | I7: https://florauruguaya.org/taxonomias/justicia-axillaris
A8: =VLOOKUP(especies_20260604_1527564[[#This Row],[Column1]],output__33[[input_name_string]:[wfo_id2]],2,FALSE) -> wfo-0000354192 | B8: Sufrútice | C8: Acanthaceae | D8: Justicia brasiliana Roth | E8: Justicia brasiliana | F8: Roth | G8: Nov. Pl. Sp. 17, 1821. | H8: Marchesi, E., Mailhos, A., & Bonifacino, J. M. (2026). Flora Uruguaya: Flora Vascular del Uruguay. ISSN 3121-2050, V. 1.3. [Data set]. Zenodo. https://doi.org/10.5281/zenodo.20547117 | I8: https://florauruguaya.org/taxonomias/justicia-brasiliana
A9: =VLOOKUP(especies_20260604_1527564[[#This Row],[Column1]],output__33[[input_name_string]:[wfo_id2]],2,FALSE) -> wfo-0000354453 | B9: Hierba perenne | C9: Acanthaceae | D9: Justicia comata (L.) Lam. | E9: Justicia comata | F9: (L.) Lam. | G9: Encycl. [J. Lamarck & al.] 1(2): 632, 1785. | H9: Marchesi, E., Mailhos, A., & Bonifacino, J. M. (2026). Flora Uruguaya: Flora Vascular del Uruguay. ISSN 3121-2050, V. 1.3. [Data set]. Zenodo. https://doi.org/10.5281/zenodo.20547117 | I9: https://florauruguaya.org/taxonomias/justicia-comata
A10: =VLOOKUP(especies_20260604_1527564[[#This Row],[Column1]],output__33[[input_name_string]:[wfo_id2]],2,FALSE) -> wfo-0000355947 | B10: Hierba perenne | C10: Acanthaceae | D10: Justicia laevilinguis (Nees) Lindau | E10: Justicia laevilinguis | F10: (Nees) Lindau | G10: Bot. Jahrb. Syst. 19(4): 20, 1894. | H10: Marchesi, E., Mailhos, A., & Bonifacino, J. M. (2026). Flora Uruguaya: Flora Vascular del Uruguay. ISSN 3121-2050, V. 1.3. [Data set]. Zenodo. https://doi.org/10.5281/zenodo.20547117 | I10: https://florauruguaya.org/taxonomias/justicia-laevilinguis
A11: =VLOOKUP(especies_20260604_1527564[[#This Row],[Column1]],output__33[[input_name_string]:[wfo_id2]],2,FALSE) -> wfo-0001044021 | B11: Hierba perenne | C11: Acanthaceae | D11: Justicia oblonga (Nees) Lindau | E11: Justicia oblonga | F11: (Nees) Lindau | G11: Nat. Pflanzenfam. [Engler & Prantl] 4(3b): 350, 1895. | H11: Marchesi, E., Mailhos, A., & Bonifacino, J. M. (2026). Flora Uruguaya: Flora Vascular del Uruguay. ISSN 3121-2050, V. 1.3. [Data set]. Zenodo. https://doi.org/10.5281/zenodo.20547117 | I11: https://florauruguaya.org/taxonomias/justicia-oblonga
A12: =VLOOKUP(especies_20260604_1527564[[#This Row],[Column1]],output__33[[input_name_string]:[wfo_id2]],2,FALSE) -> wfo-0001044033 | B12: Hierba perenne | C12: Acanthaceae | D12: Justicia polygaloides (S.Moore) Lindau | E12: Justicia polygaloides | F12: (S.Moore) Lindau | G12: Bull. Herb. Boissier 2(3): 633, 1933. | H12: Marchesi, E., Mailhos, A., & Bonifacino, J. M. (2026). Flora Uruguaya: Flora Vascular del Uruguay. ISSN 3121-2050, V. 1.3. [Data set]. Zenodo. https://doi.org/10.5281/zenodo.20547117 | I12: https://florauruguaya.org/taxonomias/justicia-polygaloides
A13: =VLOOKUP(especies_20260604_1527564[[#This Row],[Column1]],output__33[[input_name_string]:[wfo_id2]],2,FALSE) -> wfo-0001045288 | B13: Arbusto | C13: Acanthaceae | D13: Justicia tweedieana (Nees) Griseb. | E13: Justicia tweedieana | F13: (Nees) Griseb. | G13: Abh. Königl. Ges. Wiss. Göttingen 19: 225, 1874. | H13: Marchesi, E., Mailhos, A., & Bonifacino, J. M. (2026). Flora Uruguaya: Flora Vascular del Uruguay. ISSN 3121-2050, V. 1.3. [Data set]. Zenodo. https://doi.org/10.5281/zenodo.20547117 | I13: https://florauruguaya.org/taxonomias/justicia-tweedieana
... A1447: =VLOOKUP(especies_20260604_1527564[[#This Row],[Column1]],output__33[[input_name_string]:[wfo_id2]],2,FALSE) -> wfo-0000867414 | B1447: Hierba anual o bienal | C1447: Gramineae | D1447: Eragrostis barrelieri Daveau | E1447: Eragrostis barrelieri | F1447: Daveau | G1447: J. Bot. (Morot) 8: 289, 1894. | H1447: Marchesi, E., Mailhos, A., & Bonifacino, J. M. (2026). Flora Uruguaya: Flora Vascular del Uruguay. ISSN 3121-2050, V. 1.3. [Data set]. Zenodo. https://doi.org/10.5281/zenodo.20547117 | I1447: https://florauruguaya.org/taxonomias/eragrostis-barrelieri
A1448: =VLOOKUP(especies_20260604_1527564[[#This Row],[Column1]],output__33[[input_name_string]:[wfo_id2]],2,FALSE) -> #N/A | B1448: Hierba perenne | C1448: Gramineae | D1448: Eragrostis cataclasta | E1448: Eragrostis cataclasta | G1448: Fl. Ilustr. Entre Rios 2: 189, 1969. | H1448: Marchesi, E., Mailhos, A., & Bonifacino, J. M. (2026). Flora Uruguaya: Flora Vascular del Uruguay. ISSN 3121-2050, V. 1.3. [Data set]. Zenodo. https://doi.org/10.5281/zenodo.20547117 | I1448: https://florauruguaya.org/taxonomias/eragrostis-cataclasta
A1449: =VLOOKUP(especies_20260604_1527564[[#This Row],[Column1]],output__33[[input_name_string]:[wfo_id2]],2,FALSE) -> wfo-0000867548 | B1449: Hierba anual o bienal | C1449: Gramineae | D1449: Eragrostis cilianensis (All.) Vignolo ex Janch. | E1449: Eragrostis cilianensis | F1449: (All.) Vignolo ex Janch. | G1449: Mitt. Naturwiss. Vereins Univ. Wien 5(9): 110, 1907. | H1449: Marchesi, E., Mailhos, A., & Bonifacino, J. M. (2026). Flora Uruguaya: Flora Vascular del Uruguay. ISSN 3121-2050, V. 1.3. [Data set]. Zenodo. https://doi.org/10.5281/zenodo.20547117 | I1449: https://florauruguaya.org/taxonomias/eragrostis-cilianensis
A1450: =VLOOKUP(especies_20260604_1527564[[#This Row],[Column1]],output__33[[input_name_string]:[wfo_id2]],2,FALSE) -> wfo-0000867617 | B1450: Hierba perenne | C1450: Gramineae | D1450: Eragrostis curvula (Schrad.) Nees | E1450: Eragrostis curvula | F1450: (Schrad.) Nees | G1450: Fl. Afr. Austral. Ill. 397, 1841. | H1450: Marchesi, E., Mailhos, A., & Bonifacino, J. M. (2026). Flora Uruguaya: Flora Vascular del Uruguay. ISSN 3121-2050, V. 1.3. [Data set]. Zenodo. https://doi.org/10.5281/zenodo.20547117 | I1450: https://florauruguaya.org/taxonomias/eragrostis-curvula
A1451: =VLOOKUP(especies_20260604_1527564[[#This Row],[Column1]],output__33[[input_name_string]:[wfo_id2]],2,FALSE) -> wfo-0000867855 | B1451: Hierba anual o bienal | C1451: Gramineae | D1451: Eragrostis hypnoides (Lam.) Britton, Sterns & Poggenb. | E1451: Eragrostis hypnoides | F1451: (Lam.) Britton, Sterns & Poggenb. | G1451: Prelim. Cat. 69, 1888. | H1451: Marchesi, E., Mailhos, A., & Bonifacino, J. M. (2026). Flora Uruguaya: Flora Vascular del Uruguay. ISSN 3121-2050, V. 1.3. [Data set]. Zenodo. https://doi.org/10.5281/zenodo.20547117 | I1451: https://florauruguaya.org/taxonomias/eragrostis-hypnoides
A1452: =VLOOKUP(especies_20260604_1527564[[#This Row],[Column1]],output__33[[input_name_string]:[wfo_id2]],2,FALSE) -> wfo-0000867890 | B1452: Hierba anual o bienal | C1452: Gramineae | D1452: Eragrostis japonica (Thunb.) Trin. | E1452: Eragrostis japonica | F1452: (Thunb.) Trin. | G1452: Mém. Acad. Imp. Sci. Saint-Pétersbourg, Sér. 6, Sci. Math., Seconde Pt. Sci. Nat. 1: 405, 1830. | H1452: Marchesi, E., Mailhos, A., & Bonifacino, J. M. (2026). Flora Uruguaya: Flora Vascular del Uruguay. ISSN 3121-2050, V. 1.3. [Data set]. Zenodo. https://doi.org/10.5281/zenodo.20547117 | I1452: https://florauruguaya.org/taxonomias/eragrostis-japonica
A1453: =VLOOKUP(especies_20260604_1527564[[#This Row],[Column1]],output__33[[input_name_string]:[wfo_id2]],2,FALSE) -> wfo-0000867982 | B1453: Hierba perenne | C1453: Gramineae | D1453: Eragrostis lugens Nees | E1453: Eragrostis lugens | F1453: Nees | G1453: Fl. Bras. Enum. Pl. 2(1): 507, 1829. | H1453: Marchesi, E., Mailhos, A., & Bonifacino, J. M. (2026). Flora Uruguaya: Flora Vascular del Uruguay. ISSN 3121-2050, V. 1.3. [Data set]. Zenodo. https://doi.org/10.5281/zenodo.20547117 | I1453: https://florauruguaya.org/taxonomias/eragrostis-lugens
A1454: =VLOOKUP(especies_20260604_1527564[[#This Row],[Column1]],output__33[[input_name_string]:[wfo_id2]],2,FALSE) -> wfo-0000868049 | B1454: Hierba anual o bienal | C1454: Gramineae | D1454: Eragrostis mexicana (Hornem.) Link | E1454: Eragrostis mexicana | F1454: (Hornem.) Link | G1454: Hort. Berol. [Link] 1: 190, 1827. | H1454: Marchesi, E., Mailhos, A., & Bonifacino, J. M. (2026). Flora Uruguaya: Flora Vascular del Uruguay. ISSN 3121-2050, V. 1.3. [Data set]. Zenodo. https://doi.org/10.5281/zenodo.20547117 | I1454: https://florauruguaya.org/taxonomias/eragrostis-mexicana
A1455: =VLOOKUP(especies_20260604_1527564[[#This Row],[Column1]],output__33[[input_name_string]:[wfo_id2]],2,FALSE) -> wfo-0000868064 | B1455: Hierba anual o bienal | C1455: Gramineae | D1455: Eragrostis minor Host | E1455: Eragrostis minor | F1455: Host | G1455: Icon. Descr. Gram. Austriac. 4: 15, 1809. | H1455: Marchesi, E., Mailhos, A., & Bonifacino, J. M. (2026). Flora Uruguaya: Flora Vascular del Uruguay. ISSN 3121-2050, V. 1.3. [Data set]. Zenodo. https://doi.org/10.5281/zenodo.20547117 | I1455: https://florauruguaya.org/taxonomias/eragrostis-minor
A1456: =VLOOKUP(especies_20260604_1527564[[#This Row],[Column1]],output__33[[input_name_string]:[wfo_id2]],2,FALSE) -> wfo-0000868110 | B1456: Hierba perenne | C1456: Gramineae | D1456: Eragrostis neesii Trin. | E1456: Eragrostis neesii | F1456: Trin. | G1456: Mém. Acad. Imp. Sci. Saint-Pétersbourg, Sér. 6, Sci. Math., Seconde Pt. Sci. Nat. 1: 405, 1830. | H1456: Marchesi, E., Mailhos, A., & Bonifacino, J. M. (2026). Flora Uruguaya: Flora Vascular del Uruguay. ISSN 3121-2050, V. 1.3. [Data set]. Zenodo. https://doi.org/10.5281/zenodo.20547117 | I1456: https://florauruguaya.org/taxonomias/eragrostis-neesii
A1457: =VLOOKUP(especies_20260604_1527564[[#This Row],[Column1]],output__33[[input_name_string]:[wfo_id2]],2,FALSE) -> wfo-0000868188 | B1457: Hierba anual o bienal | C1457: Gramineae | D1457: Eragrostis pectinacea (Michx.) Nees | E1457: Eragrostis pectinacea | F1457: (Michx.) Nees | G1457: Fl. Afr. Austral. Ill. 406, 1841. | H1457: Marchesi, E., Mailhos, A., & Bonifacino, J. M. (2026). Flora Uruguaya: Flora Vascular del Uruguay. ISSN 3121-2050, V. 1.3. [Data set]. Zenodo. https://doi.org/10.5281/zenodo.20547117 | I1457: https://florauruguaya.org/taxonomias/eragrostis-pectinacea
A1458: =VLOOKUP(especies_20260604_1527564[[#This Row],[Column1]],output__33[[input_name_string]:[wfo_id2]],2,FALSE) -> wfo-0000868200 | B1458: Hierba perenne | C1458: Gramineae | D1458: Eragrostis perennis Döll | E1458: Eragrostis perennis | F1458: Döll | G1458: Fl. Bras. [Martius] 2(3): 144, 1878. | H1458: Marchesi, E., Mailhos, A., & Bonifacino, J. M. (2026). Flora Uruguaya: Flora Vascular del Uruguay. ISSN 3121-2050, V. 1.3. [Data set]. Zenodo. https://doi.org/10.5281/zenodo.20547117 | I1458: https://florauruguaya.org/taxonomias/eragrostis-perennis
A1459: =VLOOKUP(especies_20260604_1527564[[#This Row],[Column1]],output__33[[input_name_string]:[wfo_id2]],2,FALSE) -> wfo-0000868222 | B1459: Hierba anual o bienal | C1459: Gramineae | D1459: Eragrostis pilosa (L.) P.Beauv. | E1459: Eragrostis pilosa | F1459: (L.) P.Beauv. | G1459: Ess. Agrostogr. 71, 1812. | H1459: Marchesi, E., Mailhos, A., & Bonifacino, J. M. (2026). Flora Uruguaya: Flora Vascular del Uruguay. ISSN 3121-2050, V. 1.3. [Data set]. Zenodo. https://doi.org/10.5281/zenodo.20547117 | I1459: https://florauruguaya.org/taxonomias/eragrostis-pilosa
A1460: =VLOOKUP(especies_20260604_1527564[[#This Row],[Column1]],output__33[[input_name_string]:[wfo_id2]],2,FALSE) -> wfo-0000868250 | B1460: Hierba perenne | C1460: Gramineae | D1460: Eragrostis plana Nees | E1460: Eragrostis plana | F1460: Nees | G1460: Fl. Afr. Austral. Ill. 390, 1841. | H1460: Marchesi, E., Mailhos, A., & Bonifacino, J. M. (2026). Flora Uruguaya: Flora Vascular del Uruguay. ISSN 3121-2050, V. 1.3. [Data set]. Zenodo. https://doi.org/10.5281/zenodo.20547117 | I1460: https://florauruguaya.org/taxonomias/eragrostis-plana
... A1884: =VLOOKUP(especies_20260604_1527564[[#This Row],[Column1]],output__33[[input_name_string]:[wfo_id2]],2,FALSE) -> wfo-0000216782 | B1884: Hierba perenne | C1884: Labiatae | D1884: Hyptis lappacea Benth. | E1884: Hyptis lappacea | F1884: Benth. | G1884: Labiat. Gen. Spec. 103, 1833. | H1884: Marchesi, E., Mailhos, A., & Bonifacino, J. M. (2026). Flora Uruguaya: Flora Vascular del Uruguay. ISSN 3121-2050, V. 1.3. [Data set]. Zenodo. https://doi.org/10.5281/zenodo.20547117 | I1884: https://florauruguaya.org/taxonomias/hyptis-lappacea
A1885: =VLOOKUP(especies_20260604_1527564[[#This Row],[Column1]],output__33[[input_name_string]:[wfo_id2]],2,FALSE) -> wfo-0000216818 | B1885: Hierba anual o bienal | C1885: Labiatae | D1885: Hyptis lorentziana O.Hoffm. | E1885: Hyptis lorentziana | F1885: O.Hoffm. | H1885: Marchesi, E., Mailhos, A., & Bonifacino, J. M. (2026). Flora Uruguaya: Flora Vascular del Uruguay. ISSN 3121-2050, V. 1.3. [Data set]. Zenodo. https://doi.org/10.5281/zenodo.20547117 | I1885: https://florauruguaya.org/taxonomias/hyptis-lorentziana
A1886: =VLOOKUP(especies_20260604_1527564[[#This Row],[Column1]],output__33[[input_name_string]:[wfo_id2]],2,FALSE) -> wfo-0000216872 | B1886: Hierba perenne | C1886: Labiatae | D1886: Hyptis muelleri Briq. | E1886: Hyptis muelleri | F1886: Briq. | G1886: Bull. Soc. Bot. Genève 5: 112, 1889. | H1886: Marchesi, E., Mailhos, A., & Bonifacino, J. M. (2026). Flora Uruguaya: Flora Vascular del Uruguay. ISSN 3121-2050, V. 1.3. [Data set]. Zenodo. https://doi.org/10.5281/zenodo.20547117 | I1886: https://florauruguaya.org/taxonomias/hyptis-muelleri
A1887: =VLOOKUP(especies_20260604_1527564[[#This Row],[Column1]],output__33[[input_name_string]:[wfo_id2]],2,FALSE) -> wfo-0000222440 | B1887: Hierba anual o bienal | C1887: Labiatae | D1887: Lamium amplexicaule L. | E1887: Lamium amplexicaule | F1887: L. | G1887: Sp. Pl. [Linnaeus] 2: 579, 1753. | H1887: Marchesi, E., Mailhos, A., & Bonifacino, J. M. (2026). Flora Uruguaya: Flora Vascular del Uruguay. ISSN 3121-2050, V. 1.3. [Data set]. Zenodo. https://doi.org/10.5281/zenodo.20547117 | I1887: https://florauruguaya.org/taxonomias/lamium-amplexicaule
A1888: =VLOOKUP(especies_20260604_1527564[[#This Row],[Column1]],output__33[[input_name_string]:[wfo_id2]],2,FALSE) -> wfo-0000224580 | B1888: Hierba anual o bienal | C1888: Labiatae | D1888: Leonotis leonurus (L.) R.Br. | E1888: Leonotis leonurus | F1888: (L.) R.Br. | G1888: Hort. Kew., ed. 2 [W.T. Aiton] 3: 410, 1811. | H1888: Marchesi, E., Mailhos, A., & Bonifacino, J. M. (2026). Flora Uruguaya: Flora Vascular del Uruguay. ISSN 3121-2050, V. 1.3. [Data set]. Zenodo. https://doi.org/10.5281/zenodo.20547117 | I1888: https://florauruguaya.org/taxonomias/leonotis-leonurus
A1889: =VLOOKUP(especies_20260604_1527564[[#This Row],[Column1]],output__33[[input_name_string]:[wfo_id2]],2,FALSE) -> wfo-0000224588 | B1889: Hierba anual o bienal | C1889: Labiatae | D1889: Leonotis nepetifolia (L.) R.Br. | E1889: Leonotis nepetifolia | F1889: (L.) R.Br. | G1889: Hort. Kew., ed. 2 [W.T. Aiton] 3: 409, 1811. | H1889: Marchesi, E., Mailhos, A., & Bonifacino, J. M. (2026). Flora Uruguaya: Flora Vascular del Uruguay. ISSN 3121-2050, V. 1.3. [Data set]. Zenodo. https://doi.org/10.5281/zenodo.20547117 | I1889: https://florauruguaya.org/taxonomias/leonotis-nepetifolia
A1890: =VLOOKUP(especies_20260604_1527564[[#This Row],[Column1]],output__33[[input_name_string]:[wfo_id2]],2,FALSE) -> wfo-0000224677 | B1890: Hierba anual o bienal | C1890: Labiatae | D1890: Leonurus japonicus Houtt. | E1890: Leonurus japonicus | F1890: Houtt. | G1890: Nat. hist.. | H1890: Marchesi, E., Mailhos, A., & Bonifacino, J. M. (2026). Flora Uruguaya: Flora Vascular del Uruguay. ISSN 3121-2050, V. 1.3. [Data set]. Zenodo. https://doi.org/10.5281/zenodo.20547117 | I1890: https://florauruguaya.org/taxonomias/leonurus-japonicus
